Workbook

Sheet Inicio
A1: ⚽ LOS PIBES DE LA 12
A4: Polla Mundialista 2026 — Plantilla de Pronósticos
A6: 📝 | B6: Datos | E6: Daniel
A8: 🏟️ | B8: Fase de Grupos | E8: Pronostica el marcador de los 72 partidos
A10: 📊 | B10: Tabla Grupos | E10: Se calcula sola: 1°, 2° y mejores terceros
A12: 🏆 | B12: Eliminatorias | E12: Bracket dinámico hasta la final
A14: 🥇 | B14: Podio | E14: Tu Campeón, Subcampeón y Tercer puesto
A16: 📋 | B16: Grupos (referencia) | E16: Equipos de cada grupo
A19: ⏰ Recuerda enviar tu archivo antes del 11 de junio de 2026, 1:00 p.m. (hora Colombia). Haz clic en el nombre de cada sección para ir directo a esa pestaña. Solo escribe en las celdas con fondo amarillo y letra azul — el resto se calcula solo.

Sheet Datos
A1: ⚽ Polla Mundialista 2026 — Los Pibes de la 12
A3: Nombre completo:
A5: Instrucciones:
A6: 1. Llena la pestaña "Fase de Grupos" con el marcador exacto que crees para cada partido (ej. 2 - 1).
A7: 2. La pestaña "Tabla Grupos" calcula SOLA quién queda 1°, 2° y 3° de cada grupo, y los 8 mejores terceros.
A8: 3. En "Eliminatorias", los cruces que dependen de 1° y 2° lugar se llenan SOLOS. Para los cruces que dependen
A9: de "Mejor 3°" debes escribir tú el nombre del equipo (la app te muestra los candidatos clasificados).
A10: 4. Para cada partido eliminatorio escribe el marcador que imaginas; si crees que va a penales, escribe el
A11: ganador (1 o 2) en la columna "Penales". El ganador de cada cruce alimenta automáticamente la siguiente ronda.
A12: 5. Al final, "Eliminatorias" calcula solo el Campeón, Subcampeón y Tercer puesto.
A13: 6. Guarda el archivo con tu nombre, ej: Pronosticos_JuanPerez.xlsx
A14: 7. Envíalo por correo o WhatsApp al administrador antes del 11 de junio de 2026, 1:00 p.m. (hora Colombia).
... A18: completo de FIFA, así que en empates muy cerrados revisa manualmente si el orden te parece correcto.

Sheet Fase de Grupos
A1: 🏟️ Fase de Grupos — Pronóstico de marcador (72 partidos)
A2: # | B2: Grupo | C2: Equipo Local | D2: Goles Local | E2: Goles Visitante | F2: Equipo Visitante
A3: 1 | B3: A | C3: México | D3: 3 | E3: 0 | F3: Sudáfrica
A4: 2 | B4: A | C4: Corea del Sur | D4: 2 | E4: 1 | F4: Rep. Checa
A5: 3 | B5: A | C5: Rep. Checa | D5: 2 | E5: 0 | F5: Sudáfrica
A6: 4 | B6: A | C6: México | D6: 2 | E6: 1 | F6: Corea del Sur
A7: 5 | B7: A | C7: Rep. Checa | D7: 1 | E7: 1 | F7: México
A8: 6 | B8: A | C8: Sudáfrica | D8: 1 | E8: 2 | F8: Corea del Sur
A9: 7 | B9: B | C9: Canadá | D9: 2 | E9: 1 | F9: Bosnia y Herzegovina
A10: 8 | B10: B | C10: Qatar | D10: 1 | E10: 1 | F10: Suiza
A11: 9 | B11: B | C11: Suiza | F11: Bosnia y Herzegovina
A12: 10 | B12: B | C12: Canadá | F12: Qatar
A13: 11 | B13: B | C13: Suiza | F13: Canadá
A14: 12 | B14: B | C14: Bosnia y Herzegovina | F14: Qatar
A15: 13 | B15: C | C15: Brasil | F15: Marruecos
A16: 14 | B16: C | C16: Haití | F16: Escocia
A17: 15 | B17: C | C17: Escocia | F17: Marruecos
A18: 16 | B18: C | C18: Brasil | F18: Haití
A19: 17 | B19: C | C19: Escocia | F19: Brasil
A20: 18 | B20: C | C20: Marruecos | F20: Haití
A21: 19 | B21: D | C21: Estados Unidos | F21: Paraguay
A22: 20 | B22: D | C22: Australia | F22: Turquía
... A74: 72 | B74: L | C74: Croacia | F74: Ghana

Sheet Tabla Grupos
A1: 📊 Tabla de posiciones (se calcula sola con tus marcadores)
A2: Grupo | B2: 1° | C2: 2° | D2: 3° | E2: Pts (3°) | F2: DG (3°) | G2: GF (3°) | H2: Índice (3°) | I2: Pos. mejores 3° | J2: ¿Clasifica?
A3: Grupo A | B3: =INDEX($A$18:$A$21,MATCH(1,$G$18:$G$21,0)) -> México | C3: =INDEX($A$18:$A$21,MATCH(2,$G$18:$G$21,0)) -> Corea del Sur | D3: =INDEX($A$18:$A$21,MATCH(3,$G$18:$G$21,0)) -> Rep. Checa | E3: =INDEX($B$18:$B$21,MATCH(3,$G$18:$G$21,0)) -> 4 | F3: =INDEX($E$18:$E$21,MATCH(3,$G$18:$G$21,0)) -> 1 | G3: =INDEX($C$18:$C$21,MATCH(3,$G$18:$G$21,0)) -> 4 | H3: =E3*10000+(F3+30)*100+G3 -> 43104 | I3: =RANK(H3,$H$3:$H$14) -> 1 | J3: =IF(I3<=8,"Sí ✅","No") -> Sí ✅
A4: Grupo B | B4: =INDEX($A$24:$A$27,MATCH(1,$G$24:$G$27,0)) -> Canadá | C4: =INDEX($A$24:$A$27,MATCH(2,$G$24:$G$27,0)) -> Qatar | D4: =INDEX($A$24:$A$27,MATCH(3,$G$24:$G$27,0)) -> Suiza | E4: =INDEX($B$24:$B$27,MATCH(3,$G$24:$G$27,0)) -> 1 | F4: =INDEX($E$24:$E$27,MATCH(3,$G$24:$G$27,0)) -> 0 | G4: =INDEX($C$24:$C$27,MATCH(3,$G$24:$G$27,0)) -> 1 | H4: =E4*10000+(F4+30)*100+G4 -> 13001 | I4: =RANK(H4,$H$3:$H$14) -> 2 | J4: =IF(I4<=8,"Sí ✅","No") -> Sí ✅
A5: Grupo C | B5: =INDEX($A$30:$A$33,MATCH(1,$G$30:$G$33,0)) -> Brasil | C5: =INDEX($A$30:$A$33,MATCH(2,$G$30:$G$33,0)) -> Marruecos | D5: =INDEX($A$30:$A$33,MATCH(3,$G$30:$G$33,0)) -> Haití | E5: =INDEX($B$30:$B$33,MATCH(3,$G$30:$G$33,0)) -> 0 | F5: =INDEX($E$30:$E$33,MATCH(3,$G$30:$G$33,0)) -> 0 | G5: =INDEX($C$30:$C$33,MATCH(3,$G$30:$G$33,0)) -> 0 | H5: =E5*10000+(F5+30)*100+G5 -> 3000 | I5: =RANK(H5,$H$3:$H$14) -> 3 | J5: =IF(I5<=8,"Sí ✅","No") -> Sí ✅
A6: Grupo D | B6: =INDEX($A$36:$A$39,MATCH(1,$G$36:$G$39,0)) -> Estados Unidos | C6: =INDEX($A$36:$A$39,MATCH(2,$G$36:$G$39,0)) -> Paraguay | D6: =INDEX($A$36:$A$39,MATCH(3,$G$36:$G$39,0)) -> Australia | E6: =INDEX($B$36:$B$39,MATCH(3,$G$36:$G$39,0)) -> 0 | F6: =INDEX($E$36:$E$39,MATCH(3,$G$36:$G$39,0)) -> 0 | G6: =INDEX($C$36:$C$39,MATCH(3,$G$36:$G$39,0)) -> 0 | H6: =E6*10000+(F6+30)*100+G6 -> 3000 | I6: =RANK(H6,$H$3:$H$14) -> 3 | J6: =IF(I6<=8,"Sí ✅","No") -> Sí ✅
A7: Grupo E | B7: =INDEX($A$42:$A$45,MATCH(1,$G$42:$G$45,0)) -> Alemania | C7: =INDEX($A$42:$A$45,MATCH(2,$G$42:$G$45,0)) -> Curazao | D7: =INDEX($A$42:$A$45,MATCH(3,$G$42:$G$45,0)) -> Costa de Marfil | E7: =INDEX($B$42:$B$45,MATCH(3,$G$42:$G$45,0)) -> 0 | F7: =INDEX($E$42:$E$45,MATCH(3,$G$42:$G$45,0)) -> 0 | G7: =INDEX($C$42:$C$45,MATCH(3,$G$42:$G$45,0)) -> 0 | H7: =E7*10000+(F7+30)*100+G7 -> 3000 | I7: =RANK(H7,$H$3:$H$14) -> 3 | J7: =IF(I7<=8,"Sí ✅","No") -> Sí ✅
A8: Grupo F | B8: =INDEX($A$48:$A$51,MATCH(1,$G$48:$G$51,0)) -> Países Bajos | C8: =INDEX($A$48:$A$51,MATCH(2,$G$48:$G$51,0)) -> Japón | D8: =INDEX($A$48:$A$51,MATCH(3,$G$48:$G$51,0)) -> Suecia | E8: =INDEX($B$48:$B$51,MATCH(3,$G$48:$G$51,0)) -> 0 | F8: =INDEX($E$48:$E$51,MATCH(3,$G$48:$G$51,0)) -> 0 | G8: =INDEX($C$48:$C$51,MATCH(3,$G$48:$G$51,0)) -> 0 | H8: =E8*10000+(F8+30)*100+G8 -> 3000 | I8: =RANK(H8,$H$3:$H$14) -> 3 | J8: =IF(I8<=8,"Sí ✅","No") -> Sí ✅
A9: Grupo G | B9: =INDEX($A$54:$A$57,MATCH(1,$G$54:$G$57,0)) -> Bélgica | C9: =INDEX($A$54:$A$57,MATCH(2,$G$54:$G$57,0)) -> Egipto | D9: =INDEX($A$54:$A$57,MATCH(3,$G$54:$G$57,0)) -> Irán | E9: =INDEX($B$54:$B$57,MATCH(3,$G$54:$G$57,0)) -> 0 | F9: =INDEX($E$54:$E$57,MATCH(3,$G$54:$G$57,0)) -> 0 | G9: =INDEX($C$54:$C$57,MATCH(3,$G$54:$G$57,0)) -> 0 | H9: =E9*10000+(F9+30)*100+G9 -> 3000 | I9: =RANK(H9,$H$3:$H$14) -> 3 | J9: =IF(I9<=8,"Sí ✅","No") -> Sí ✅
A10: Grupo H | B10: =INDEX($A$60:$A$63,MATCH(1,$G$60:$G$63,0)) -> España | C10: =INDEX($A$60:$A$63,MATCH(2,$G$60:$G$63,0)) -> Cabo Verde | D10: =INDEX($A$60:$A$63,MATCH(3,$G$60:$G$63,0)) -> Arabia Saudita | E10: =INDEX($B$60:$B$63,MATCH(3,$G$60:$G$63,0)) -> 0 | F10: =INDEX($E$60:$E$63,MATCH(3,$G$60:$G$63,0)) -> 0 | G10: =INDEX($C$60:$C$63,MATCH(3,$G$60:$G$63,0)) -> 0 | H10: =E10*10000+(F10+30)*100+G10 -> 3000 | I10: =RANK(H10,$H$3:$H$14) -> 3 | J10: =IF(I10<=8,"Sí ✅","No") -> Sí ✅
A11: Grupo I | B11: =INDEX($A$66:$A$69,MATCH(1,$G$66:$G$69,0)) -> Francia | C11: =INDEX($A$66:$A$69,MATCH(2,$G$66:$G$69,0)) -> Senegal | D11: =INDEX($A$66:$A$69,MATCH(3,$G$66:$G$69,0)) -> Irak | E11: =INDEX($B$66:$B$69,MATCH(3,$G$66:$G$69,0)) -> 0 | F11: =INDEX($E$66:$E$69,MATCH(3,$G$66:$G$69,0)) -> 0 | G11: =INDEX($C$66:$C$69,MATCH(3,$G$66:$G$69,0)) -> 0 | H11: =E11*10000+(F11+30)*100+G11 -> 3000 | I11: =RANK(H11,$H$3:$H$14) -> 3 | J11: =IF(I11<=8,"Sí ✅","No") -> Sí ✅
A12: Grupo J | B12: =INDEX($A$72:$A$75,MATCH(1,$G$72:$G$75,0)) -> Argentina | C12: =INDEX($A$72:$A$75,MATCH(2,$G$72:$G$75,0)) -> Argelia | D12: =INDEX($A$72:$A$75,MATCH(3,$G$72:$G$75,0)) -> Austria | E12: =INDEX($B$72:$B$75,MATCH(3,$G$72:$G$75,0)) -> 0 | F12: =INDEX($E$72:$E$75,MATCH(3,$G$72:$G$75,0)) -> 0 | G12: =INDEX($C$72:$C$75,MATCH(3,$G$72:$G$75,0)) -> 0 | H12: =E12*10000+(F12+30)*100+G12 -> 3000 | I12: =RANK(H12,$H$3:$H$14) -> 3 | J12: =IF(I12<=8,"Sí ✅","No") -> Sí ✅
A13: Grupo K | B13: =INDEX($A$78:$A$81,MATCH(1,$G$78:$G$81,0)) -> Portugal | C13: =INDEX($A$78:$A$81,MATCH(2,$G$78:$G$81,0)) -> Rep. Dem. del Congo | D13: =INDEX($A$78:$A$81,MATCH(3,$G$78:$G$81,0)) -> Uzbekistán | E13: =INDEX($B$78:$B$81,MATCH(3,$G$78:$G$81,0)) -> 0 | F13: =INDEX($E$78:$E$81,MATCH(3,$G$78:$G$81,0)) -> 0 | G13: =INDEX($C$78:$C$81,MATCH(3,$G$78:$G$81,0)) -> 0 | H13: =E13*10000+(F13+30)*100+G13 -> 3000 | I13: =RANK(H13,$H$3:$H$14) -> 3 | J13: =IF(I13<=8,"Sí ✅","No") -> Sí ✅
A14: Grupo L | B14: =INDEX($A$84:$A$87,MATCH(1,$G$84:$G$87,0)) -> Inglaterra | C14: =INDEX($A$84:$A$87,MATCH(2,$G$84:$G$87,0)) -> Croacia | D14: =INDEX($A$84:$A$87,MATCH(3,$G$84:$G$87,0)) -> Ghana | E14: =INDEX($B$84:$B$87,MATCH(3,$G$84:$G$87,0)) -> 0 | F14: =INDEX($E$84:$E$87,MATCH(3,$G$84:$G$87,0)) -> 0 | G14: =INDEX($C$84:$C$87,MATCH(3,$G$84:$G$87,0)) -> 0 | H14: =E14*10000+(F14+30)*100+G14 -> 3000 | I14: =RANK(H14,$H$3:$H$14) -> 3 | J14: =IF(I14<=8,"Sí ✅","No") -> Sí ✅
A17: Grupo A | B17: Pts | C17: GF | D17: GC | E17: DG | F17: Índice | G17: Pos.
A18: México | B18: =SUMPRODUCT(('Fase de Grupos'!$C$3:$C$8=$A18)*ISNUMBER('Fase de Grupos'!$D$3:$D$8)*ISNUMBER('Fase de Grupos'!$E$3:$E$8)*('Fase de Grupos'!$D$3:$D$8>'Fase de Grupos'!$E$3:$E$8))*3+SUMPRODUCT(('Fase de Grupos'!$F$3:$F$8=$A18)*ISNUMBER('Fase de Grupos'!$D$3:$D$8)*ISNUMBER('Fase de Grupos'!$E$3:$E$8)*('Fase de Grupos'!$E$3:$E$8>'Fase de Grupos'!$D$3:$D$8))*3+SUMPRODUCT(('Fase de Grupos'!$C$3:$C$8=$A18)*ISNUMBER('Fase de Grupos'!$D$3:$D$8)*ISNUMBER('Fase de Grupos'!$E$3:$E$8)*('Fase de Grupos'!$D$3:$D$8='Fase de Grupos'!$E$3:$E$8))+SUMPRODUCT(('Fase de Grupos'!$F$3:$F$8=$A18)*ISNUMBER('Fase de Grupos'!$D$3:$D$8)*ISNUMBER('Fase de Grupos'!$E$3:$E$8)*('Fase de Grupos'!$E$3:$E$8='Fase de Grupos'!$D$3:$D$8)) -> 7 | C18: =SUMPRODUCT(('Fase de Grupos'!$C$3:$C$8=$A18)*ISNUMBER('Fase de Grupos'!$D$3:$D$8)*ISNUMBER('Fase de Grupos'!$E$3:$E$8)*'Fase de Grupos'!$D$3:$D$8)+SUMPRODUCT(('Fase de Grupos'!$F$3:$F$8=$A18)*ISNUMBER('Fase de Grupos'!$D$3:$D$8)*ISNUMBER('Fase de Grupos'!$E$3:$E$8)*'Fase de Grupos'!$E$3:$E$8) -> 6 | D18: =SUMPRODUCT(('Fase de Grupos'!$C$3:$C$8=$A18)*ISNUMBER('Fase de Grupos'!$D$3:$D$8)*ISNUMBER('Fase de Grupos'!$E$3:$E$8)*'Fase de Grupos'!$E$3:$E$8)+SUMPRODUCT(('Fase de Grupos'!$F$3:$F$8=$A18)*ISNUMBER('Fase de Grupos'!$D$3:$D$8)*ISNUMBER('Fase de Grupos'!$E$3:$E$8)*'Fase de Grupos'!$D$3:$D$8) -> 2 | E18: =C18-D18 -> 4 | F18: =B18*10000+(E18+30)*100+C18-0*0.001 -> 73406 | G18: =RANK(F18,$F$18:$F$21) -> 1
A19: Sudáfrica | B19: =SUMPRODUCT(('Fase de Grupos'!$C$3:$C$8=$A19)*ISNUMBER('Fase de Grupos'!$D$3:$D$8)*ISNUMBER('Fase de Grupos'!$E$3:$E$8)*('Fase de Grupos'!$D$3:$D$8>'Fase de Grupos'!$E$3:$E$8))*3+SUMPRODUCT(('Fase de Grupos'!$F$3:$F$8=$A19)*ISNUMBER('Fase de Grupos'!$D$3:$D$8)*ISNUMBER('Fase de Grupos'!$E$3:$E$8)*('Fase de Grupos'!$E$3:$E$8>'Fase de Grupos'!$D$3:$D$8))*3+SUMPRODUCT(('Fase de Grupos'!$C$3:$C$8=$A19)*ISNUMBER('Fase de Grupos'!$D$3:$D$8)*ISNUMBER('Fase de Grupos'!$E$3:$E$8)*('Fase de Grupos'!$D$3:$D$8='Fase de Grupos'!$E$3:$E$8))+SUMPRODUCT(('Fase de Grupos'!$F$3:$F$8=$A19)*ISNUMBER('Fase de Grupos'!$D$3:$D$8)*ISNUMBER('Fase de Grupos'!$E$3:$E$8)*('Fase de Grupos'!$E$3:$E$8='Fase de Grupos'!$D$3:$D$8)) -> 0 | C19: =SUMPRODUCT(('Fase de Grupos'!$C$3:$C$8=$A19)*ISNUMBER('Fase de Grupos'!$D$3:$D$8)*ISNUMBER('Fase de Grupos'!$E$3:$E$8)*'Fase de Grupos'!$D$3:$D$8)+SUMPRODUCT(('Fase de Grupos'!$F$3:$F$8=$A19)*ISNUMBER('Fase de Grupos'!$D$3:$D$8)*ISNUMBER('Fase de Grupos'!$E$3:$E$8)*'Fase de Grupos'!$E$3:$E$8) -> 1 | D19: =SUMPRODUCT(('Fase de Grupos'!$C$3:$C$8=$A19)*ISNUMBER('Fase de Grupos'!$D$3:$D$8)*ISNUMBER('Fase de Grupos'!$E$3:$E$8)*'Fase de Grupos'!$E$3:$E$8)+SUMPRODUCT(('Fase de Grupos'!$F$3:$F$8=$A19)*ISNUMBER('Fase de Grupos'!$D$3:$D$8)*ISNUMBER('Fase de Grupos'!$E$3:$E$8)*'Fase de Grupos'!$D$3:$D$8) -> 7 | E19: =C19-D19 -> -6 | F19: =B19*10000+(E19+30)*100+C19-1*0.001 -> 2400.999 | G19: =RANK(F19,$F$18:$F$21) -> 4
A20: Corea del Sur | B20: =SUMPRODUCT(('Fase de Grupos'!$C$3:$C$8=$A20)*ISNUMBER('Fase de Grupos'!$D$3:$D$8)*ISNUMBER('Fase de Grupos'!$E$3:$E$8)*('Fase de Grupos'!$D$3:$D$8>'Fase de Grupos'!$E$3:$E$8))*3+SUMPRODUCT(('Fase de Grupos'!$F$3:$F$8=$A20)*ISNUMBER('Fase de Grupos'!$D$3:$D$8)*ISNUMBER('Fase de Grupos'!$E$3:$E$8)*('Fase de Grupos'!$E$3:$E$8>'Fase de Grupos'!$D$3:$D$8))*3+SUMPRODUCT(('Fase de Grupos'!$C$3:$C$8=$A20)*ISNUMBER('Fase de Grupos'!$D$3:$D$8)*ISNUMBER('Fase de Grupos'!$E$3:$E$8)*('Fase de Grupos'!$D$3:$D$8='Fase de Grupos'!$E$3:$E$8))+SUMPRODUCT(('Fase de Grupos'!$F$3:$F$8=$A20)*ISNUMBER('Fase de Grupos'!$D$3:$D$8)*ISNUMBER('Fase de Grupos'!$E$3:$E$8)*('Fase de Grupos'!$E$3:$E$8='Fase de Grupos'!$D$3:$D$8)) -> 6 | C20: =SUMPRODUCT(('Fase de Grupos'!$C$3:$C$8=$A20)*ISNUMBER('Fase de Grupos'!$D$3:$D$8)*ISNUMBER('Fase de Grupos'!$E$3:$E$8)*'Fase de Grupos'!$D$3:$D$8)+SUMPRODUCT(('Fase de Grupos'!$F$3:$F$8=$A20)*ISNUMBER('Fase de Grupos'!$D$3:$D$8)*ISNUMBER('Fase de Grupos'!$E$3:$E$8)*'Fase de Grupos'!$E$3:$E$8) -> 5 | D20: =SUMPRODUCT(('Fase de Grupos'!$C$3:$C$8=$A20)*ISNUMBER('Fase de Grupos'!$D$3:$D$8)*ISNUMBER('Fase de Grupos'!$E$3:$E$8)*'Fase de Grupos'!$E$3:$E$8)+SUMPRODUCT(('Fase de Grupos'!$F$3:$F$8=$A20)*ISNUMBER('Fase de Grupos'!$D$3:$D$8)*ISNUMBER('Fase de Grupos'!$E$3:$E$8)*'Fase de Grupos'!$D$3:$D$8) -> 4 | E20: =C20-D20 -> 1 | F20: =B20*10000+(E20+30)*100+C20-2*0.001 -> 63104.998 | G20: =RANK(F20,$F$18:$F$21) -> 2
A21: Rep. Checa | B21: =SUMPRODUCT(('Fase de Grupos'!$C$3:$C$8=$A21)*ISNUMBER('Fase de Grupos'!$D$3:$D$8)*ISNUMBER('Fase de Grupos'!$E$3:$E$8)*('Fase de Grupos'!$D$3:$D$8>'Fase de Grupos'!$E$3:$E$8))*3+SUMPRODUCT(('Fase de Grupos'!$F$3:$F$8=$A21)*ISNUMBER('Fase de Grupos'!$D$3:$D$8)*ISNUMBER('Fase de Grupos'!$E$3:$E$8)*('Fase de Grupos'!$E$3:$E$8>'Fase de Grupos'!$D$3:$D$8))*3+SUMPRODUCT(('Fase de Grupos'!$C$3:$C$8=$A21)*ISNUMBER('Fase de Grupos'!$D$3:$D$8)*ISNUMBER('Fase de Grupos'!$E$3:$E$8)*('Fase de Grupos'!$D$3:$D$8='Fase de Grupos'!$E$3:$E$8))+SUMPRODUCT(('Fase de Grupos'!$F$3:$F$8=$A21)*ISNUMBER('Fase de Grupos'!$D$3:$D$8)*ISNUMBER('Fase de Grupos'!$E$3:$E$8)*('Fase de Grupos'!$E$3:$E$8='Fase de Grupos'!$D$3:$D$8)) -> 4 | C21: =SUMPRODUCT(('Fase de Grupos'!$C$3:$C$8=$A21)*ISNUMBER('Fase de Grupos'!$D$3:$D$8)*ISNUMBER('Fase de Grupos'!$E$3:$E$8)*'Fase de Grupos'!$D$3:$D$8)+SUMPRODUCT(('Fase de Grupos'!$F$3:$F$8=$A21)*ISNUMBER('Fase de Grupos'!$D$3:$D$8)*ISNUMBER('Fase de Grupos'!$E$3:$E$8)*'Fase de Grupos'!$E$3:$E$8) -> 4 | D21: =SUMPRODUCT(('Fase de Grupos'!$C$3:$C$8=$A21)*ISNUMBER('Fase de Grupos'!$D$3:$D$8)*ISNUMBER('Fase de Grupos'!$E$3:$E$8)*'Fase de Grupos'!$E$3:$E$8)+SUMPRODUCT(('Fase de Grupos'!$F$3:$F$8=$A21)*ISNUMBER('Fase de Grupos'!$D$3:$D$8)*ISNUMBER('Fase de Grupos'!$E$3:$E$8)*'Fase de Grupos'!$D$3:$D$8) -> 3 | E21: =C21-D21 -> 1 | F21: =B21*10000+(E21+30)*100+C21-3*0.001 -> 43103.997 | G21: =RANK(F21,$F$18:$F$21) -> 3
A23: Grupo B | B23: Pts | C23: GF | D23: GC | E23: DG | F23: Índice | G23: Pos.
A24: Canadá | B24: =SUMPRODUCT(('Fase de Grupos'!$C$9:$C$14=$A24)*ISNUMBER('Fase de Grupos'!$D$9:$D$14)*ISNUMBER('Fase de Grupos'!$E$9:$E$14)*('Fase de Grupos'!$D$9:$D$14>'Fase de Grupos'!$E$9:$E$14))*3+SUMPRODUCT(('Fase de Grupos'!$F$9:$F$14=$A24)*ISNUMBER('Fase de Grupos'!$D$9:$D$14)*ISNUMBER('Fase de Grupos'!$E$9:$E$14)*('Fase de Grupos'!$E$9:$E$14>'Fase de Grupos'!$D$9:$D$14))*3+SUMPRODUCT(('Fase de Grupos'!$C$9:$C$14=$A24)*ISNUMBER('Fase de Grupos'!$D$9:$D$14)*ISNUMBER('Fase de Grupos'!$E$9:$E$14)*('Fase de Grupos'!$D$9:$D$14='Fase de Grupos'!$E$9:$E$14))+SUMPRODUCT(('Fase de Grupos'!$F$9:$F$14=$A24)*ISNUMBER('Fase de Grupos'!$D$9:$D$14)*ISNUMBER('Fase de Grupos'!$E$9:$E$14)*('Fase de Grupos'!$E$9:$E$14='Fase de Grupos'!$D$9:$D$14)) -> 3 | C24: =SUMPRODUCT(('Fase de Grupos'!$C$9:$C$14=$A24)*ISNUMBER('Fase de Grupos'!$D$9:$D$14)*ISNUMBER('Fase de Grupos'!$E$9:$E$14)*'Fase de Grupos'!$D$9:$D$14)+SUMPRODUCT(('Fase de Grupos'!$F$9:$F$14=$A24)*ISNUMBER('Fase de Grupos'!$D$9:$D$14)*ISNUMBER('Fase de Grupos'!$E$9:$E$14)*'Fase de Grupos'!$E$9:$E$14) -> 2 | D24: =SUMPRODUCT(('Fase de Grupos'!$C$9:$C$14=$A24)*ISNUMBER('Fase de Grupos'!$D$9:$D$14)*ISNUMBER('Fase de Grupos'!$E$9:$E$14)*'Fase de Grupos'!$E$9:$E$14)+SUMPRODUCT(('Fase de Grupos'!$F$9:$F$14=$A24)*ISNUMBER('Fase de Grupos'!$D$9:$D$14)*ISNUMBER('Fase de Grupos'!$E$9:$E$14)*'Fase de Grupos'!$D$9:$D$14) -> 1 | E24: =C24-D24 -> 1 | F24: =B24*10000+(E24+30)*100+C24-0*0.001 -> 33102 | G24: =RANK(F24,$F$24:$F$27) -> 1
A25: Bosnia y Herzegovina | B25: =SUMPRODUCT(('Fase de Grupos'!$C$9:$C$14=$A25)*ISNUMBER('Fase de Grupos'!$D$9:$D$14)*ISNUMBER('Fase de Grupos'!$E$9:$E$14)*('Fase de Grupos'!$D$9:$D$14>'Fase de Grupos'!$E$9:$E$14))*3+SUMPRODUCT(('Fase de Grupos'!$F$9:$F$14=$A25)*ISNUMBER('Fase de Grupos'!$D$9:$D$14)*ISNUMBER('Fase de Grupos'!$E$9:$E$14)*('Fase de Grupos'!$E$9:$E$14>'Fase de Grupos'!$D$9:$D$14))*3+SUMPRODUCT(('Fase de Grupos'!$C$9:$C$14=$A25)*ISNUMBER('Fase de Grupos'!$D$9:$D$14)*ISNUMBER('Fase de Grupos'!$E$9:$E$14)*('Fase de Grupos'!$D$9:$D$14='Fase de Grupos'!$E$9:$E$14))+SUMPRODUCT(('Fase de Grupos'!$F$9:$F$14=$A25)*ISNUMBER('Fase de Grupos'!$D$9:$D$14)*ISNUMBER('Fase de Grupos'!$E$9:$E$14)*('Fase de Grupos'!$E$9:$E$14='Fase de Grupos'!$D$9:$D$14)) -> 0 | C25: =SUMPRODUCT(('Fase de Grupos'!$C$9:$C$14=$A25)*ISNUMBER('Fase de Grupos'!$D$9:$D$14)*ISNUMBER('Fase de Grupos'!$E$9:$E$14)*'Fase de Grupos'!$D$9:$D$14)+SUMPRODUCT(('Fase de Grupos'!$F$9:$F$14=$A25)*ISNUMBER('Fase de Grupos'!$D$9:$D$14)*ISNUMBER('Fase de Grupos'!$E$9:$E$14)*'Fase de Grupos'!$E$9:$E$14) -> 1 | D25: =SUMPRODUCT(('Fase de Grupos'!$C$9:$C$14=$A25)*ISNUMBER('Fase de Grupos'!$D$9:$D$14)*ISNUMBER('Fase de Grupos'!$E$9:$E$14)*'Fase de Grupos'!$E$9:$E$14)+SUMPRODUCT(('Fase de Grupos'!$F$9:$F$14=$A25)*ISNUMBER('Fase de Grupos'!$D$9:$D$14)*ISNUMBER('Fase de Grupos'!$E$9:$E$14)*'Fase de Grupos'!$D$9:$D$14) -> 2 | E25: =C25-D25 -> -1 | F25: =B25*10000+(E25+30)*100+C25-1*0.001 -> 2900.999 | G25: =RANK(F25,$F$24:$F$27) -> 4
A26: Qatar | B26: =SUMPRODUCT(('Fase de Grupos'!$C$9:$C$14=$A26)*ISNUMBER('Fase de Grupos'!$D$9:$D$14)*ISNUMBER('Fase de Grupos'!$E$9:$E$14)*('Fase de Grupos'!$D$9:$D$14>'Fase de Grupos'!$E$9:$E$14))*3+SUMPRODUCT(('Fase de Grupos'!$F$9:$F$14=$A26)*ISNUMBER('Fase de Grupos'!$D$9:$D$14)*ISNUMBER('Fase de Grupos'!$E$9:$E$14)*('Fase de Grupos'!$E$9:$E$14>'Fase de Grupos'!$D$9:$D$14))*3+SUMPRODUCT(('Fase de Grupos'!$C$9:$C$14=$A26)*ISNUMBER('Fase de Grupos'!$D$9:$D$14)*ISNUMBER('Fase de Grupos'!$E$9:$E$14)*('Fase de Grupos'!$D$9:$D$14='Fase de Grupos'!$E$9:$E$14))+SUMPRODUCT(('Fase de Grupos'!$F$9:$F$14=$A26)*ISNUMBER('Fase de Grupos'!$D$9:$D$14)*ISNUMBER('Fase de Grupos'!$E$9:$E$14)*('Fase de Grupos'!$E$9:$E$14='Fase de Grupos'!$D$9:$D$14)) -> 1 | C26: =SUMPRODUCT(('Fase de Grupos'!$C$9:$C$14=$A26)*ISNUMBER('Fase de Grupos'!$D$9:$D$14)*ISNUMBER('Fase de Grupos'!$E$9:$E$14)*'Fase de Grupos'!$D$9:$D$14)+SUMPRODUCT(('Fase de Grupos'!$F$9:$F$14=$A26)*ISNUMBER('Fase de Grupos'!$D$9:$D$14)*ISNUMBER('Fase de Grupos'!$E$9:$E$14)*'Fase de Grupos'!$E$9:$E$14) -> 1 | D26: =SUMPRODUCT(('Fase de Grupos'!$C$9:$C$14=$A26)*ISNUMBER('Fase de Grupos'!$D$9:$D$14)*ISNUMBER('Fase de Grupos'!$E$9:$E$14)*'Fase de Grupos'!$E$9:$E$14)+SUMPRODUCT(('Fase de Grupos'!$F$9:$F$14=$A26)*ISNUMBER('Fase de Grupos'!$D$9:$D$14)*ISNUMBER('Fase de Grupos'!$E$9:$E$14)*'Fase de Grupos'!$D$9:$D$14) -> 1 | E26: =C26-D26 -> 0 | F26: =B26*10000+(E26+30)*100+C26-2*0.001 -> 13000.998 | G26: =RANK(F26,$F$24:$F$27) -> 2
A27: Suiza | B27: =SUMPRODUCT(('Fase de Grupos'!$C$9:$C$14=$A27)*ISNUMBER('Fase de Grupos'!$D$9:$D$14)*ISNUMBER('Fase de Grupos'!$E$9:$E$14)*('Fase de Grupos'!$D$9:$D$14>'Fase de Grupos'!$E$9:$E$14))*3+SUMPRODUCT(('Fase de Grupos'!$F$9:$F$14=$A27)*ISNUMBER('Fase de Grupos'!$D$9:$D$14)*ISNUMBER('Fase de Grupos'!$E$9:$E$14)*('Fase de Grupos'!$E$9:$E$14>'Fase de Grupos'!$D$9:$D$14))*3+SUMPRODUCT(('Fase de Grupos'!$C$9:$C$14=$A27)*ISNUMBER('Fase de Grupos'!$D$9:$D$14)*ISNUMBER('Fase de Grupos'!$E$9:$E$14)*('Fase de Grupos'!$D$9:$D$14='Fase de Grupos'!$E$9:$E$14))+SUMPRODUCT(('Fase de Grupos'!$F$9:$F$14=$A27)*ISNUMBER('Fase de Grupos'!$D$9:$D$14)*ISNUMBER('Fase de Grupos'!$E$9:$E$14)*('Fase de Grupos'!$E$9:$E$14='Fase de Grupos'!$D$9:$D$14)) -> 1 | C27: =SUMPRODUCT(('Fase de Grupos'!$C$9:$C$14=$A27)*ISNUMBER('Fase de Grupos'!$D$9:$D$14)*ISNUMBER('Fase de Grupos'!$E$9:$E$14)*'Fase de Grupos'!$D$9:$D$14)+SUMPRODUCT(('Fase de Grupos'!$F$9:$F$14=$A27)*ISNUMBER('Fase de Grupos'!$D$9:$D$14)*ISNUMBER('Fase de Grupos'!$E$9:$E$14)*'Fase de Grupos'!$E$9:$E$14) -> 1 | D27: =SUMPRODUCT(('Fase de Grupos'!$C$9:$C$14=$A27)*ISNUMBER('Fase de Grupos'!$D$9:$D$14)*ISNUMBER('Fase de Grupos'!$E$9:$E$14)*'Fase de Grupos'!$E$9:$E$14)+SUMPRODUCT(('Fase de Grupos'!$F$9:$F$14=$A27)*ISNUMBER('Fase de Grupos'!$D$9:$D$14)*ISNUMBER('Fase de Grupos'!$E$9:$E$14)*'Fase de Grupos'!$D$9:$D$14) -> 1 | E27: =C27-D27 -> 0 | F27: =B27*10000+(E27+30)*100+C27-3*0.001 -> 13000.997 | G27: =RANK(F27,$F$24:$F$27) -> 3
A29: Grupo C | B29: Pts | C29: GF | D29: GC | E29: DG | F29: Índice | G29: Pos.
A30: Brasil | B30: =SUMPRODUCT(('Fase de Grupos'!$C$15:$C$20=$A30)*ISNUMBER('Fase de Grupos'!$D$15:$D$20)*ISNUMBER('Fase de Grupos'!$E$15:$E$20)*('Fase de Grupos'!$D$15:$D$20>'Fase de Grupos'!$E$15:$E$20))*3+SUMPRODUCT(('Fase de Grupos'!$F$15:$F$20=$A30)*ISNUMBER('Fase de Grupos'!$D$15:$D$20)*ISNUMBER('Fase de Grupos'!$E$15:$E$20)*('Fase de Grupos'!$E$15:$E$20>'Fase de Grupos'!$D$15:$D$20))*3+SUMPRODUCT(('Fase de Grupos'!$C$15:$C$20=$A30)*ISNUMBER('Fase de Grupos'!$D$15:$D$20)*ISNUMBER('Fase de Grupos'!$E$15:$E$20)*('Fase de Grupos'!$D$15:$D$20='Fase de Grupos'!$E$15:$E$20))+SUMPRODUCT(('Fase de Grupos'!$F$15:$F$20=$A30)*ISNUMBER('Fase de Grupos'!$D$15:$D$20)*ISNUMBER('Fase de Grupos'!$E$15:$E$20)*('Fase de Grupos'!$E$15:$E$20='Fase de Grupos'!$D$15:$D$20)) -> 0 | C30: =SUMPRODUCT(('Fase de Grupos'!$C$15:$C$20=$A30)*ISNUMBER('Fase de Grupos'!$D$15:$D$20)*ISNUMBER('Fase de Grupos'!$E$15:$E$20)*'Fase de Grupos'!$D$15:$D$20)+SUMPRODUCT(('Fase de Grupos'!$F$15:$F$20=$A30)*ISNUMBER('Fase de Grupos'!$D$15:$D$20)*ISNUMBER('Fase de Grupos'!$E$15:$E$20)*'Fase de Grupos'!$E$15:$E$20) -> 0 | D30: =SUMPRODUCT(('Fase de Grupos'!$C$15:$C$20=$A30)*ISNUMBER('Fase de Grupos'!$D$15:$D$20)*ISNUMBER('Fase de Grupos'!$E$15:$E$20)*'Fase de Grupos'!$E$15:$E$20)+SUMPRODUCT(('Fase de Grupos'!$F$15:$F$20=$A30)*ISNUMBER('Fase de Grupos'!$D$15:$D$20)*ISNUMBER('Fase de Grupos'!$E$15:$E$20)*'Fase de Grupos'!$D$15:$D$20) -> 0 | E30: =C30-D30 -> 0 | F30: =B30*10000+(E30+30)*100+C30-0*0.001 -> 3000 | G30: =RANK(F30,$F$30:$F$33) -> 1
A31: Marruecos | B31: =SUMPRODUCT(('Fase de Grupos'!$C$15:$C$20=$A31)*ISNUMBER('Fase de Grupos'!$D$15:$D$20)*ISNUMBER('Fase de Grupos'!$E$15:$E$20)*('Fase de Grupos'!$D$15:$D$20>'Fase de Grupos'!$E$15:$E$20))*3+SUMPRODUCT(('Fase de Grupos'!$F$15:$F$20=$A31)*ISNUMBER('Fase de Grupos'!$D$15:$D$20)*ISNUMBER('Fase de Grupos'!$E$15:$E$20)*('Fase de Grupos'!$E$15:$E$20>'Fase de Grupos'!$D$15:$D$20))*3+SUMPRODUCT(('Fase de Grupos'!$C$15:$C$20=$A31)*ISNUMBER('Fase de Grupos'!$D$15:$D$20)*ISNUMBER('Fase de Grupos'!$E$15:$E$20)*('Fase de Grupos'!$D$15:$D$20='Fase de Grupos'!$E$15:$E$20))+SUMPRODUCT(('Fase de Grupos'!$F$15:$F$20=$A31)*ISNUMBER('Fase de Grupos'!$D$15:$D$20)*ISNUMBER('Fase de Grupos'!$E$15:$E$20)*('Fase de Grupos'!$E$15:$E$20='Fase de Grupos'!$D$15:$D$20)) -> 0 | C31: =SUMPRODUCT(('Fase de Grupos'!$C$15:$C$20=$A31)*ISNUMBER('Fase de Grupos'!$D$15:$D$20)*ISNUMBER('Fase de Grupos'!$E$15:$E$20)*'Fase de Grupos'!$D$15:$D$20)+SUMPRODUCT(('Fase de Grupos'!$F$15:$F$20=$A31)*ISNUMBER('Fase de Grupos'!$D$15:$D$20)*ISNUMBER('Fase de Grupos'!$E$15:$E$20)*'Fase de Grupos'!$E$15:$E$20) -> 0 | D31: =SUMPRODUCT(('Fase de Grupos'!$C$15:$C$20=$A31)*ISNUMBER('Fase de Grupos'!$D$15:$D$20)*ISNUMBER('Fase de Grupos'!$E$15:$E$20)*'Fase de Grupos'!$E$15:$E$20)+SUMPRODUCT(('Fase de Grupos'!$F$15:$F$20=$A31)*ISNUMBER('Fase de Grupos'!$D$15:$D$20)*ISNUMBER('Fase de Grupos'!$E$15:$E$20)*'Fase de Grupos'!$D$15:$D$20) -> 0 | E31: =C31-D31 -> 0 | F31: =B31*10000+(E31+30)*100+C31-1*0.001 -> 2999.999 | G31: =RANK(F31,$F$30:$F$33) -> 2
A32: Haití | B32: =SUMPRODUCT(('Fase de Grupos'!$C$15:$C$20=$A32)*ISNUMBER('Fase de Grupos'!$D$15:$D$20)*ISNUMBER('Fase de Grupos'!$E$15:$E$20)*('Fase de Grupos'!$D$15:$D$20>'Fase de Grupos'!$E$15:$E$20))*3+SUMPRODUCT(('Fase de Grupos'!$F$15:$F$20=$A32)*ISNUMBER('Fase de Grupos'!$D$15:$D$20)*ISNUMBER('Fase de Grupos'!$E$15:$E$20)*('Fase de Grupos'!$E$15:$E$20>'Fase de Grupos'!$D$15:$D$20))*3+SUMPRODUCT(('Fase de Grupos'!$C$15:$C$20=$A32)*ISNUMBER('Fase de Grupos'!$D$15:$D$20)*ISNUMBER('Fase de Grupos'!$E$15:$E$20)*('Fase de Grupos'!$D$15:$D$20='Fase de Grupos'!$E$15:$E$20))+SUMPRODUCT(('Fase de Grupos'!$F$15:$F$20=$A32)*ISNUMBER('Fase de Grupos'!$D$15:$D$20)*ISNUMBER('Fase de Grupos'!$E$15:$E$20)*('Fase de Grupos'!$E$15:$E$20='Fase de Grupos'!$D$15:$D$20)) -> 0 | C32: =SUMPRODUCT(('Fase de Grupos'!$C$15:$C$20=$A32)*ISNUMBER('Fase de Grupos'!$D$15:$D$20)*ISNUMBER('Fase de Grupos'!$E$15:$E$20)*'Fase de Grupos'!$D$15:$D$20)+SUMPRODUCT(('Fase de Grupos'!$F$15:$F$20=$A32)*ISNUMBER('Fase de Grupos'!$D$15:$D$20)*ISNUMBER('Fase de Grupos'!$E$15:$E$20)*'Fase de Grupos'!$E$15:$E$20) -> 0 | D32: =SUMPRODUCT(('Fase de Grupos'!$C$15:$C$20=$A32)*ISNUMBER('Fase de Grupos'!$D$15:$D$20)*ISNUMBER('Fase de Grupos'!$E$15:$E$20)*'Fase de Grupos'!$E$15:$E$20)+SUMPRODUCT(('Fase de Grupos'!$F$15:$F$20=$A32)*ISNUMBER('Fase de Grupos'!$D$15:$D$20)*ISNUMBER('Fase de Grupos'!$E$15:$E$20)*'Fase de Grupos'!$D$15:$D$20) -> 0 | E32: =C32-D32 -> 0 | F32: =B32*10000+(E32+30)*100+C32-2*0.001 -> 2999.998 | G32: =RANK(F32,$F$30:$F$33) -> 3
A33: Escocia | B33: =SUMPRODUCT(('Fase de Grupos'!$C$15:$C$20=$A33)*ISNUMBER('Fase de Grupos'!$D$15:$D$20)*ISNUMBER('Fase de Grupos'!$E$15:$E$20)*('Fase de Grupos'!$D$15:$D$20>'Fase de Grupos'!$E$15:$E$20))*3+SUMPRODUCT(('Fase de Grupos'!$F$15:$F$20=$A33)*ISNUMBER('Fase de Grupos'!$D$15:$D$20)*ISNUMBER('Fase de Grupos'!$E$15:$E$20)*('Fase de Grupos'!$E$15:$E$20>'Fase de Grupos'!$D$15:$D$20))*3+SUMPRODUCT(('Fase de Grupos'!$C$15:$C$20=$A33)*ISNUMBER('Fase de Grupos'!$D$15:$D$20)*ISNUMBER('Fase de Grupos'!$E$15:$E$20)*('Fase de Grupos'!$D$15:$D$20='Fase de Grupos'!$E$15:$E$20))+SUMPRODUCT(('Fase de Grupos'!$F$15:$F$20=$A33)*ISNUMBER('Fase de Grupos'!$D$15:$D$20)*ISNUMBER('Fase de Grupos'!$E$15:$E$20)*('Fase de Grupos'!$E$15:$E$20='Fase de Grupos'!$D$15:$D$20)) -> 0 | C33: =SUMPRODUCT(('Fase de Grupos'!$C$15:$C$20=$A33)*ISNUMBER('Fase de Grupos'!$D$15:$D$20)*ISNUMBER('Fase de Grupos'!$E$15:$E$20)*'Fase de Grupos'!$D$15:$D$20)+SUMPRODUCT(('Fase de Grupos'!$F$15:$F$20=$A33)*ISNUMBER('Fase de Grupos'!$D$15:$D$20)*ISNUMBER('Fase de Grupos'!$E$15:$E$20)*'Fase de Grupos'!$E$15:$E$20) -> 0 | D33: =SUMPRODUCT(('Fase de Grupos'!$C$15:$C$20=$A33)*ISNUMBER('Fase de Grupos'!$D$15:$D$20)*ISNUMBER('Fase de Grupos'!$E$15:$E$20)*'Fase de Grupos'!$E$15:$E$20)+SUMPRODUCT(('Fase de Grupos'!$F$15:$F$20=$A33)*ISNUMBER('Fase de Grupos'!$D$15:$D$20)*ISNUMBER('Fase de Grupos'!$E$15:$E$20)*'Fase de Grupos'!$D$15:$D$20) -> 0 | E33: =C33-D33 -> 0 | F33: =B33*10000+(E33+30)*100+C33-3*0.001 -> 2999.997 | G33: =RANK(F33,$F$30:$F$33) -> 4
A35: Grupo D | B35: Pts | C35: GF | D35: GC | E35: DG | F35: Índice | G35: Pos.
A36: Estados Unidos | B36: =SUMPRODUCT(('Fase de Grupos'!$C$21:$C$26=$A36)*ISNUMBER('Fase de Grupos'!$D$21:$D$26)*ISNUMBER('Fase de Grupos'!$E$21:$E$26)*('Fase de Grupos'!$D$21:$D$26>'Fase de Grupos'!$E$21:$E$26))*3+SUMPRODUCT(('Fase de Grupos'!$F$21:$F$26=$A36)*ISNUMBER('Fase de Grupos'!$D$21:$D$26)*ISNUMBER('Fase de Grupos'!$E$21:$E$26)*('Fase de Grupos'!$E$21:$E$26>'Fase de Grupos'!$D$21:$D$26))*3+SUMPRODUCT(('Fase de Grupos'!$C$21:$C$26=$A36)*ISNUMBER('Fase de Grupos'!$D$21:$D$26)*ISNUMBER('Fase de Grupos'!$E$21:$E$26)*('Fase de Grupos'!$D$21:$D$26='Fase de Grupos'!$E$21:$E$26))+SUMPRODUCT(('Fase de Grupos'!$F$21:$F$26=$A36)*ISNUMBER('Fase de Grupos'!$D$21:$D$26)*ISNUMBER('Fase de Grupos'!$E$21:$E$26)*('Fase de Grupos'!$E$21:$E$26='Fase de Grupos'!$D$21:$D$26)) -> 0 | C36: =SUMPRODUCT(('Fase de Grupos'!$C$21:$C$26=$A36)*ISNUMBER('Fase de Grupos'!$D$21:$D$26)*ISNUMBER('Fase de Grupos'!$E$21:$E$26)*'Fase de Grupos'!$D$21:$D$26)+SUMPRODUCT(('Fase de Grupos'!$F$21:$F$26=$A36)*ISNUMBER('Fase de Grupos'!$D$21:$D$26)*ISNUMBER('Fase de Grupos'!$E$21:$E$26)*'Fase de Grupos'!$E$21:$E$26) -> 0 | D36: =SUMPRODUCT(('Fase de Grupos'!$C$21:$C$26=$A36)*ISNUMBER('Fase de Grupos'!$D$21:$D$26)*ISNUMBER('Fase de Grupos'!$E$21:$E$26)*'Fase de Grupos'!$E$21:$E$26)+SUMPRODUCT(('Fase de Grupos'!$F$21:$F$26=$A36)*ISNUMBER('Fase de Grupos'!$D$21:$D$26)*ISNUMBER('Fase de Grupos'!$E$21:$E$26)*'Fase de Grupos'!$D$21:$D$26) -> 0 | E36: =C36-D36 -> 0 | F36: =B36*10000+(E36+30)*100+C36-0*0.001 -> 3000 | G36: =RANK(F36,$F$36:$F$39) -> 1
A37: Paraguay | B37: =SUMPRODUCT(('Fase de Grupos'!$C$21:$C$26=$A37)*ISNUMBER('Fase de Grupos'!$D$21:$D$26)*ISNUMBER('Fase de Grupos'!$E$21:$E$26)*('Fase de Grupos'!$D$21:$D$26>'Fase de Grupos'!$E$21:$E$26))*3+SUMPRODUCT(('Fase de Grupos'!$F$21:$F$26=$A37)*ISNUMBER('Fase de Grupos'!$D$21:$D$26)*ISNUMBER('Fase de Grupos'!$E$21:$E$26)*('Fase de Grupos'!$E$21:$E$26>'Fase de Grupos'!$D$21:$D$26))*3+SUMPRODUCT(('Fase de Grupos'!$C$21:$C$26=$A37)*ISNUMBER('Fase de Grupos'!$D$21:$D$26)*ISNUMBER('Fase de Grupos'!$E$21:$E$26)*('Fase de Grupos'!$D$21:$D$26='Fase de Grupos'!$E$21:$E$26))+SUMPRODUCT(('Fase de Grupos'!$F$21:$F$26=$A37)*ISNUMBER('Fase de Grupos'!$D$21:$D$26)*ISNUMBER('Fase de Grupos'!$E$21:$E$26)*('Fase de Grupos'!$E$21:$E$26='Fase de Grupos'!$D$21:$D$26)) -> 0 | C37: =SUMPRODUCT(('Fase de Grupos'!$C$21:$C$26=$A37)*ISNUMBER('Fase de Grupos'!$D$21:$D$26)*ISNUMBER('Fase de Grupos'!$E$21:$E$26)*'Fase de Grupos'!$D$21:$D$26)+SUMPRODUCT(('Fase de Grupos'!$F$21:$F$26=$A37)*ISNUMBER('Fase de Grupos'!$D$21:$D$26)*ISNUMBER('Fase de Grupos'!$E$21:$E$26)*'Fase de Grupos'!$E$21:$E$26) -> 0 | D37: =SUMPRODUCT(('Fase de Grupos'!$C$21:$C$26=$A37)*ISNUMBER('Fase de Grupos'!$D$21:$D$26)*ISNUMBER('Fase de Grupos'!$E$21:$E$26)*'Fase de Grupos'!$E$21:$E$26)+SUMPRODUCT(('Fase de Grupos'!$F$21:$F$26=$A37)*ISNUMBER('Fase de Grupos'!$D$21:$D$26)*ISNUMBER('Fase de Grupos'!$E$21:$E$26)*'Fase de Grupos'!$D$21:$D$26) -> 0 | E37: =C37-D37 -> 0 | F37: =B37*10000+(E37+30)*100+C37-1*0.001 -> 2999.999 | G37: =RANK(F37,$F$36:$F$39) -> 2
A38: Australia | B38: =SUMPRODUCT(('Fase de Grupos'!$C$21:$C$26=$A38)*ISNUMBER('Fase de Grupos'!$D$21:$D$26)*ISNUMBER('Fase de Grupos'!$E$21:$E$26)*('Fase de Grupos'!$D$21:$D$26>'Fase de Grupos'!$E$21:$E$26))*3+SUMPRODUCT(('Fase de Grupos'!$F$21:$F$26=$A38)*ISNUMBER('Fase de Grupos'!$D$21:$D$26)*ISNUMBER('Fase de Grupos'!$E$21:$E$26)*('Fase de Grupos'!$E$21:$E$26>'Fase de Grupos'!$D$21:$D$26))*3+SUMPRODUCT(('Fase de Grupos'!$C$21:$C$26=$A38)*ISNUMBER('Fase de Grupos'!$D$21:$D$26)*ISNUMBER('Fase de Grupos'!$E$21:$E$26)*('Fase de Grupos'!$D$21:$D$26='Fase de Grupos'!$E$21:$E$26))+SUMPRODUCT(('Fase de Grupos'!$F$21:$F$26=$A38)*ISNUMBER('Fase de Grupos'!$D$21:$D$26)*ISNUMBER('Fase de Grupos'!$E$21:$E$26)*('Fase de Grupos'!$E$21:$E$26='Fase de Grupos'!$D$21:$D$26)) -> 0 | C38: =SUMPRODUCT(('Fase de Grupos'!$C$21:$C$26=$A38)*ISNUMBER('Fase de Grupos'!$D$21:$D$26)*ISNUMBER('Fase de Grupos'!$E$21:$E$26)*'Fase de Grupos'!$D$21:$D$26)+SUMPRODUCT(('Fase de Grupos'!$F$21:$F$26=$A38)*ISNUMBER('Fase de Grupos'!$D$21:$D$26)*ISNUMBER('Fase de Grupos'!$E$21:$E$26)*'Fase de Grupos'!$E$21:$E$26) -> 0 | D38: =SUMPRODUCT(('Fase de Grupos'!$C$21:$C$26=$A38)*ISNUMBER('Fase de Grupos'!$D$21:$D$26)*ISNUMBER('Fase de Grupos'!$E$21:$E$26)*'Fase de Grupos'!$E$21:$E$26)+SUMPRODUCT(('Fase de Grupos'!$F$21:$F$26=$A38)*ISNUMBER('Fase de Grupos'!$D$21:$D$26)*ISNUMBER('Fase de Grupos'!$E$21:$E$26)*'Fase de Grupos'!$D$21:$D$26) -> 0 | E38: =C38-D38 -> 0 | F38: =B38*10000+(E38+30)*100+C38-2*0.001 -> 2999.998 | G38: =RANK(F38,$F$36:$F$39) -> 3
A39: Turquía | B39: =SUMPRODUCT(('Fase de Grupos'!$C$21:$C$26=$A39)*ISNUMBER('Fase de Grupos'!$D$21:$D$26)*ISNUMBER('Fase de Grupos'!$E$21:$E$26)*('Fase de Grupos'!$D$21:$D$26>'Fase de Grupos'!$E$21:$E$26))*3+SUMPRODUCT(('Fase de Grupos'!$F$21:$F$26=$A39)*ISNUMBER('Fase de Grupos'!$D$21:$D$26)*ISNUMBER('Fase de Grupos'!$E$21:$E$26)*('Fase de Grupos'!$E$21:$E$26>'Fase de Grupos'!$D$21:$D$26))*3+SUMPRODUCT(('Fase de Grupos'!$C$21:$C$26=$A39)*ISNUMBER('Fase de Grupos'!$D$21:$D$26)*ISNUMBER('Fase de Grupos'!$E$21:$E$26)*('Fase de Grupos'!$D$21:$D$26='Fase de Grupos'!$E$21:$E$26))+SUMPRODUCT(('Fase de Grupos'!$F$21:$F$26=$A39)*ISNUMBER('Fase de Grupos'!$D$21:$D$26)*ISNUMBER('Fase de Grupos'!$E$21:$E$26)*('Fase de Grupos'!$E$21:$E$26='Fase de Grupos'!$D$21:$D$26)) -> 0 | C39: =SUMPRODUCT(('Fase de Grupos'!$C$21:$C$26=$A39)*ISNUMBER('Fase de Grupos'!$D$21:$D$26)*ISNUMBER('Fase de Grupos'!$E$21:$E$26)*'Fase de Grupos'!$D$21:$D$26)+SUMPRODUCT(('Fase de Grupos'!$F$21:$F$26=$A39)*ISNUMBER('Fase de Grupos'!$D$21:$D$26)*ISNUMBER('Fase de Grupos'!$E$21:$E$26)*'Fase de Grupos'!$E$21:$E$26) -> 0 | D39: =SUMPRODUCT(('Fase de Grupos'!$C$21:$C$26=$A39)*ISNUMBER('Fase de Grupos'!$D$21:$D$26)*ISNUMBER('Fase de Grupos'!$E$21:$E$26)*'Fase de Grupos'!$E$21:$E$26)+SUMPRODUCT(('Fase de Grupos'!$F$21:$F$26=$A39)*ISNUMBER('Fase de Grupos'!$D$21:$D$26)*ISNUMBER('Fase de Grupos'!$E$21:$E$26)*'Fase de Grupos'!$D$21:$D$26) -> 0 | E39: =C39-D39 -> 0 | F39: =B39*10000+(E39+30)*100+C39-3*0.001 -> 2999.997 | G39: =RANK(F39,$F$36:$F$39) -> 4
A41: Grupo E | B41: Pts | C41: GF | D41: GC | E41: DG | F41: Índice | G41: Pos.
A42: Alemania | B42: =SUMPRODUCT(('Fase de Grupos'!$C$27:$C$32=$A42)*ISNUMBER('Fase de Grupos'!$D$27:$D$32)*ISNUMBER('Fase de Grupos'!$E$27:$E$32)*('Fase de Grupos'!$D$27:$D$32>'Fase de Grupos'!$E$27:$E$32))*3+SUMPRODUCT(('Fase de Grupos'!$F$27:$F$32=$A42)*ISNUMBER('Fase de Grupos'!$D$27:$D$32)*ISNUMBER('Fase de Grupos'!$E$27:$E$32)*('Fase de Grupos'!$E$27:$E$32>'Fase de Grupos'!$D$27:$D$32))*3+SUMPRODUCT(('Fase de Grupos'!$C$27:$C$32=$A42)*ISNUMBER('Fase de Grupos'!$D$27:$D$32)*ISNUMBER('Fase de Grupos'!$E$27:$E$32)*('Fase de Grupos'!$D$27:$D$32='Fase de Grupos'!$E$27:$E$32))+SUMPRODUCT(('Fase de Grupos'!$F$27:$F$32=$A42)*ISNUMBER('Fase de Grupos'!$D$27:$D$32)*ISNUMBER('Fase de Grupos'!$E$27:$E$32)*('Fase de Grupos'!$E$27:$E$32='Fase de Grupos'!$D$27:$D$32)) -> 0 | C42: =SUMPRODUCT(('Fase de Grupos'!$C$27:$C$32=$A42)*ISNUMBER('Fase de Grupos'!$D$27:$D$32)*ISNUMBER('Fase de Grupos'!$E$27:$E$32)*'Fase de Grupos'!$D$27:$D$32)+SUMPRODUCT(('Fase de Grupos'!$F$27:$F$32=$A42)*ISNUMBER('Fase de Grupos'!$D$27:$D$32)*ISNUMBER('Fase de Grupos'!$E$27:$E$32)*'Fase de Grupos'!$E$27:$E$32) -> 0 | D42: =SUMPRODUCT(('Fase de Grupos'!$C$27:$C$32=$A42)*ISNUMBER('Fase de Grupos'!$D$27:$D$32)*ISNUMBER('Fase de Grupos'!$E$27:$E$32)*'Fase de Grupos'!$E$27:$E$32)+SUMPRODUCT(('Fase de Grupos'!$F$27:$F$32=$A42)*ISNUMBER('Fase de Grupos'!$D$27:$D$32)*ISNUMBER('Fase de Grupos'!$E$27:$E$32)*'Fase de Grupos'!$D$27:$D$32) -> 0 | E42: =C42-D42 -> 0 | F42: =B42*10000+(E42+30)*100+C42-0*0.001 -> 3000 | G42: =RANK(F42,$F$42:$F$45) -> 1
A43: Curazao | B43: =SUMPRODUCT(('Fase de Grupos'!$C$27:$C$32=$A43)*ISNUMBER('Fase de Grupos'!$D$27:$D$32)*ISNUMBER('Fase de Grupos'!$E$27:$E$32)*('Fase de Grupos'!$D$27:$D$32>'Fase de Grupos'!$E$27:$E$32))*3+SUMPRODUCT(('Fase de Grupos'!$F$27:$F$32=$A43)*ISNUMBER('Fase de Grupos'!$D$27:$D$32)*ISNUMBER('Fase de Grupos'!$E$27:$E$32)*('Fase de Grupos'!$E$27:$E$32>'Fase de Grupos'!$D$27:$D$32))*3+SUMPRODUCT(('Fase de Grupos'!$C$27:$C$32=$A43)*ISNUMBER('Fase de Grupos'!$D$27:$D$32)*ISNUMBER('Fase de Grupos'!$E$27:$E$32)*('Fase de Grupos'!$D$27:$D$32='Fase de Grupos'!$E$27:$E$32))+SUMPRODUCT(('Fase de Grupos'!$F$27:$F$32=$A43)*ISNUMBER('Fase de Grupos'!$D$27:$D$32)*ISNUMBER('Fase de Grupos'!$E$27:$E$32)*('Fase de Grupos'!$E$27:$E$32='Fase de Grupos'!$D$27:$D$32)) -> 0 | C43: =SUMPRODUCT(('Fase de Grupos'!$C$27:$C$32=$A43)*ISNUMBER('Fase de Grupos'!$D$27:$D$32)*ISNUMBER('Fase de Grupos'!$E$27:$E$32)*'Fase de Grupos'!$D$27:$D$32)+SUMPRODUCT(('Fase de Grupos'!$F$27:$F$32=$A43)*ISNUMBER('Fase de Grupos'!$D$27:$D$32)*ISNUMBER('Fase de Grupos'!$E$27:$E$32)*'Fase de Grupos'!$E$27:$E$32) -> 0 | D43: =SUMPRODUCT(('Fase de Grupos'!$C$27:$C$32=$A43)*ISNUMBER('Fase de Grupos'!$D$27:$D$32)*ISNUMBER('Fase de Grupos'!$E$27:$E$32)*'Fase de Grupos'!$E$27:$E$32)+SUMPRODUCT(('Fase de Grupos'!$F$27:$F$32=$A43)*ISNUMBER('Fase de Grupos'!$D$27:$D$32)*ISNUMBER('Fase de Grupos'!$E$27:$E$32)*'Fase de Grupos'!$D$27:$D$32) -> 0 | E43: =C43-D43 -> 0 | F43: =B43*10000+(E43+30)*100+C43-1*0.001 -> 2999.999 | G43: =RANK(F43,$F$42:$F$45) -> 2
A44: Costa de Marfil | B44: =SUMPRODUCT(('Fase de Grupos'!$C$27:$C$32=$A44)*ISNUMBER('Fase de Grupos'!$D$27:$D$32)*ISNUMBER('Fase de Grupos'!$E$27:$E$32)*('Fase de Grupos'!$D$27:$D$32>'Fase de Grupos'!$E$27:$E$32))*3+SUMPRODUCT(('Fase de Grupos'!$F$27:$F$32=$A44)*ISNUMBER('Fase de Grupos'!$D$27:$D$32)*ISNUMBER('Fase de Grupos'!$E$27:$E$32)*('Fase de Grupos'!$E$27:$E$32>'Fase de Grupos'!$D$27:$D$32))*3+SUMPRODUCT(('Fase de Grupos'!$C$27:$C$32=$A44)*ISNUMBER('Fase de Grupos'!$D$27:$D$32)*ISNUMBER('Fase de Grupos'!$E$27:$E$32)*('Fase de Grupos'!$D$27:$D$32='Fase de Grupos'!$E$27:$E$32))+SUMPRODUCT(('Fase de Grupos'!$F$27:$F$32=$A44)*ISNUMBER('Fase de Grupos'!$D$27:$D$32)*ISNUMBER('Fase de Grupos'!$E$27:$E$32)*('Fase de Grupos'!$E$27:$E$32='Fase de Grupos'!$D$27:$D$32)) -> 0 | C44: =SUMPRODUCT(('Fase de Grupos'!$C$27:$C$32=$A44)*ISNUMBER('Fase de Grupos'!$D$27:$D$32)*ISNUMBER('Fase de Grupos'!$E$27:$E$32)*'Fase de Grupos'!$D$27:$D$32)+SUMPRODUCT(('Fase de Grupos'!$F$27:$F$32=$A44)*ISNUMBER('Fase de Grupos'!$D$27:$D$32)*ISNUMBER('Fase de Grupos'!$E$27:$E$32)*'Fase de Grupos'!$E$27:$E$32) -> 0 | D44: =SUMPRODUCT(('Fase de Grupos'!$C$27:$C$32=$A44)*ISNUMBER('Fase de Grupos'!$D$27:$D$32)*ISNUMBER('Fase de Grupos'!$E$27:$E$32)*'Fase de Grupos'!$E$27:$E$32)+SUMPRODUCT(('Fase de Grupos'!$F$27:$F$32=$A44)*ISNUMBER('Fase de Grupos'!$D$27:$D$32)*ISNUMBER('Fase de Grupos'!$E$27:$E$32)*'Fase de Grupos'!$D$27:$D$32) -> 0 | E44: =C44-D44 -> 0 | F44: =B44*10000+(E44+30)*100+C44-2*0.001 -> 2999.998 | G44: =RANK(F44,$F$42:$F$45) -> 3
A45: Ecuador | B45: =SUMPRODUCT(('Fase de Grupos'!$C$27:$C$32=$A45)*ISNUMBER('Fase de Grupos'!$D$27:$D$32)*ISNUMBER('Fase de Grupos'!$E$27:$E$32)*('Fase de Grupos'!$D$27:$D$32>'Fase de Grupos'!$E$27:$E$32))*3+SUMPRODUCT(('Fase de Grupos'!$F$27:$F$32=$A45)*ISNUMBER('Fase de Grupos'!$D$27:$D$32)*ISNUMBER('Fase de Grupos'!$E$27:$E$32)*('Fase de Grupos'!$E$27:$E$32>'Fase de Grupos'!$D$27:$D$32))*3+SUMPRODUCT(('Fase de Grupos'!$C$27:$C$32=$A45)*ISNUMBER('Fase de Grupos'!$D$27:$D$32)*ISNUMBER('Fase de Grupos'!$E$27:$E$32)*('Fase de Grupos'!$D$27:$D$32='Fase de Grupos'!$E$27:$E$32))+SUMPRODUCT(('Fase de Grupos'!$F$27:$F$32=$A45)*ISNUMBER('Fase de Grupos'!$D$27:$D$32)*ISNUMBER('Fase de Grupos'!$E$27:$E$32)*('Fase de Grupos'!$E$27:$E$32='Fase de Grupos'!$D$27:$D$32)) -> 0 | C45: =SUMPRODUCT(('Fase de Grupos'!$C$27:$C$32=$A45)*ISNUMBER('Fase de Grupos'!$D$27:$D$32)*ISNUMBER('Fase de Grupos'!$E$27:$E$32)*'Fase de Grupos'!$D$27:$D$32)+SUMPRODUCT(('Fase de Grupos'!$F$27:$F$32=$A45)*ISNUMBER('Fase de Grupos'!$D$27:$D$32)*ISNUMBER('Fase de Grupos'!$E$27:$E$32)*'Fase de Grupos'!$E$27:$E$32) -> 0 | D45: =SUMPRODUCT(('Fase de Grupos'!$C$27:$C$32=$A45)*ISNUMBER('Fase de Grupos'!$D$27:$D$32)*ISNUMBER('Fase de Grupos'!$E$27:$E$32)*'Fase de Grupos'!$E$27:$E$32)+SUMPRODUCT(('Fase de Grupos'!$F$27:$F$32=$A45)*ISNUMBER('Fase de Grupos'!$D$27:$D$32)*ISNUMBER('Fase de Grupos'!$E$27:$E$32)*'Fase de Grupos'!$D$27:$D$32) -> 0 | E45: =C45-D45 -> 0 | F45: =B45*10000+(E45+30)*100+C45-3*0.001 -> 2999.997 | G45: =RANK(F45,$F$42:$F$45) -> 4
A47: Grupo F | B47: Pts | C47: GF | D47: GC | E47: DG | F47: Índice | G47: Pos.
...

Sheet Eliminatorias
A1: 🏆 Fase Eliminatoria — Bracket oficial FIFA (32 partidos)
A2: Los equipos de 1° y 2° lugar se llenan SOLOS desde "Tabla Grupos". Para los cruces "Mejor 3°", escribe TÚ el nombre del equipo (revisa la columna "¿Clasifica?" en Tabla Grupos para ver cuáles de los 12 terceros pasan, y elige uno de los grupos indicados entre paréntesis). Llena Goles 1 / Goles 2; si terminan empatados, escribe 1 ó 2 en "Penales" para indicar el ganador.
A3: Partido # | B3: Fase | C3: Equipo 1 | D3: Equipo 2 | E3: Goles 1 | F3: Goles 2 | G3: Penales (1 ó 2) | H3: Ganador | I3: Perdedor
A4: 73 | B4: Dieciseisavos | C4: ='Tabla Grupos'!C3 -> Corea del Sur | D4: ='Tabla Grupos'!C4 -> Qatar | H4: =IF(OR(C4="",D4=""),"",IF(OR(E4="",F4=""),"",IF(E4>F4,C4,IF(F4>E4,D4,IF(G4=1,C4,IF(G4=2,D4,"¿Penales?")))))) | I4: =IF(OR(C4="",D4=""),"",IF(OR(E4="",F4=""),"",IF(E4>F4,D4,IF(F4>E4,C4,IF(G4=1,D4,IF(G4=2,C4,"¿Penales?"))))))
A5: 74 | B5: Dieciseisavos | C5: ='Tabla Grupos'!B7 -> Alemania | H5: =IF(OR(C5="",D5=""),"",IF(OR(E5="",F5=""),"",IF(E5>F5,C5,IF(F5>E5,D5,IF(G5=1,C5,IF(G5=2,D5,"¿Penales?")))))) | I5: =IF(OR(C5="",D5=""),"",IF(OR(E5="",F5=""),"",IF(E5>F5,D5,IF(F5>E5,C5,IF(G5=1,D5,IF(G5=2,C5,"¿Penales?"))))))
A6: 75 | B6: Dieciseisavos | C6: ='Tabla Grupos'!B8 -> Países Bajos | D6: ='Tabla Grupos'!C5 -> Marruecos | H6: =IF(OR(C6="",D6=""),"",IF(OR(E6="",F6=""),"",IF(E6>F6,C6,IF(F6>E6,D6,IF(G6=1,C6,IF(G6=2,D6,"¿Penales?")))))) | I6: =IF(OR(C6="",D6=""),"",IF(OR(E6="",F6=""),"",IF(E6>F6,D6,IF(F6>E6,C6,IF(G6=1,D6,IF(G6=2,C6,"¿Penales?"))))))
A7: 76 | B7: Dieciseisavos | C7: ='Tabla Grupos'!B5 -> Brasil | D7: ='Tabla Grupos'!C8 -> Japón | H7: =IF(OR(C7="",D7=""),"",IF(OR(E7="",F7=""),"",IF(E7>F7,C7,IF(F7>E7,D7,IF(G7=1,C7,IF(G7=2,D7,"¿Penales?")))))) | I7: =IF(OR(C7="",D7=""),"",IF(OR(E7="",F7=""),"",IF(E7>F7,D7,IF(F7>E7,C7,IF(G7=1,D7,IF(G7=2,C7,"¿Penales?"))))))
A8: 77 | B8: Dieciseisavos | C8: ='Tabla Grupos'!B11 -> Francia | H8: =IF(OR(C8="",D8=""),"",IF(OR(E8="",F8=""),"",IF(E8>F8,C8,IF(F8>E8,D8,IF(G8=1,C8,IF(G8=2,D8,"¿Penales?")))))) | I8: =IF(OR(C8="",D8=""),"",IF(OR(E8="",F8=""),"",IF(E8>F8,D8,IF(F8>E8,C8,IF(G8=1,D8,IF(G8=2,C8,"¿Penales?"))))))
A9: 78 | B9: Dieciseisavos | C9: ='Tabla Grupos'!C7 -> Curazao | D9: ='Tabla Grupos'!C11 -> Senegal | H9: =IF(OR(C9="",D9=""),"",IF(OR(E9="",F9=""),"",IF(E9>F9,C9,IF(F9>E9,D9,IF(G9=1,C9,IF(G9=2,D9,"¿Penales?")))))) | I9: =IF(OR(C9="",D9=""),"",IF(OR(E9="",F9=""),"",IF(E9>F9,D9,IF(F9>E9,C9,IF(G9=1,D9,IF(G9=2,C9,"¿Penales?"))))))
A10: 79 | B10: Dieciseisavos | C10: ='Tabla Grupos'!B3 -> México | H10: =IF(OR(C10="",D10=""),"",IF(OR(E10="",F10=""),"",IF(E10>F10,C10,IF(F10>E10,D10,IF(G10=1,C10,IF(G10=2,D10,"¿Penales?")))))) | I10: =IF(OR(C10="",D10=""),"",IF(OR(E10="",F10=""),"",IF(E10>F10,D10,IF(F10>E10,C10,IF(G10=1,D10,IF(G10=2,C10,"¿Penales?"))))))
A11: 80 | B11: Dieciseisavos | C11: ='Tabla Grupos'!B14 -> Inglaterra | H11: =IF(OR(C11="",D11=""),"",IF(OR(E11="",F11=""),"",IF(E11>F11,C11,IF(F11>E11,D11,IF(G11=1,C11,IF(G11=2,D11,"¿Penales?")))))) | I11: =IF(OR(C11="",D11=""),"",IF(OR(E11="",F11=""),"",IF(E11>F11,D11,IF(F11>E11,C11,IF(G11=1,D11,IF(G11=2,C11,"¿Penales?"))))))
A12: 81 | B12: Dieciseisavos | C12: ='Tabla Grupos'!B6 -> Estados Unidos | H12: =IF(OR(C12="",D12=""),"",IF(OR(E12="",F12=""),"",IF(E12>F12,C12,IF(F12>E12,D12,IF(G12=1,C12,IF(G12=2,D12,"¿Penales?")))))) | I12: =IF(OR(C12="",D12=""),"",IF(OR(E12="",F12=""),"",IF(E12>F12,D12,IF(F12>E12,C12,IF(G12=1,D12,IF(G12=2,C12,"¿Penales?"))))))
A13: 82 | B13: Dieciseisavos | C13: ='Tabla Grupos'!B9 -> Bélgica | H13: =IF(OR(C13="",D13=""),"",IF(OR(E13="",F13=""),"",IF(E13>F13,C13,IF(F13>E13,D13,IF(G13=1,C13,IF(G13=2,D13,"¿Penales?")))))) | I13: =IF(OR(C13="",D13=""),"",IF(OR(E13="",F13=""),"",IF(E13>F13,D13,IF(F13>E13,C13,IF(G13=1,D13,IF(G13=2,C13,"¿Penales?"))))))
A14: 83 | B14: Dieciseisavos | C14: ='Tabla Grupos'!C13 -> Rep. Dem. del Congo | D14: ='Tabla Grupos'!C14 -> Croacia | H14: =IF(OR(C14="",D14=""),"",IF(OR(E14="",F14=""),"",IF(E14>F14,C14,IF(F14>E14,D14,IF(G14=1,C14,IF(G14=2,D14,"¿Penales?")))))) | I14: =IF(OR(C14="",D14=""),"",IF(OR(E14="",F14=""),"",IF(E14>F14,D14,IF(F14>E14,C14,IF(G14=1,D14,IF(G14=2,C14,"¿Penales?"))))))
A15: 84 | B15: Dieciseisavos | C15: ='Tabla Grupos'!B10 -> España | D15: ='Tabla Grupos'!C12 -> Argelia | H15: =IF(OR(C15="",D15=""),"",IF(OR(E15="",F15=""),"",IF(E15>F15,C15,IF(F15>E15,D15,IF(G15=1,C15,IF(G15=2,D15,"¿Penales?")))))) | I15: =IF(OR(C15="",D15=""),"",IF(OR(E15="",F15=""),"",IF(E15>F15,D15,IF(F15>E15,C15,IF(G15=1,D15,IF(G15=2,C15,"¿Penales?"))))))
A16: 85 | B16: Dieciseisavos | C16: ='Tabla Grupos'!B4 -> Canadá | H16: =IF(OR(C16="",D16=""),"",IF(OR(E16="",F16=""),"",IF(E16>F16,C16,IF(F16>E16,D16,IF(G16=1,C16,IF(G16=2,D16,"¿Penales?")))))) | I16: =IF(OR(C16="",D16=""),"",IF(OR(E16="",F16=""),"",IF(E16>F16,D16,IF(F16>E16,C16,IF(G16=1,D16,IF(G16=2,C16,"¿Penales?"))))))
A17: 86 | B17: Dieciseisavos | C17: ='Tabla Grupos'!B12 -> Argentina | D17: ='Tabla Grupos'!C10 -> Cabo Verde | H17: =IF(OR(C17="",D17=""),"",IF(OR(E17="",F17=""),"",IF(E17>F17,C17,IF(F17>E17,D17,IF(G17=1,C17,IF(G17=2,D17,"¿Penales?")))))) | I17: =IF(OR(C17="",D17=""),"",IF(OR(E17="",F17=""),"",IF(E17>F17,D17,IF(F17>E17,C17,IF(G17=1,D17,IF(G17=2,C17,"¿Penales?"))))))
A18: 87 | B18: Dieciseisavos | C18: ='Tabla Grupos'!B13 -> Portugal | H18: =IF(OR(C18="",D18=""),"",IF(OR(E18="",F18=""),"",IF(E18>F18,C18,IF(F18>E18,D18,IF(G18=1,C18,IF(G18=2,D18,"¿Penales?")))))) | I18: =IF(OR(C18="",D18=""),"",IF(OR(E18="",F18=""),"",IF(E18>F18,D18,IF(F18>E18,C18,IF(G18=1,D18,IF(G18=2,C18,"¿Penales?"))))))
A19: 88 | B19: Dieciseisavos | C19: ='Tabla Grupos'!C6 -> Paraguay | D19: ='Tabla Grupos'!C9 -> Egipto | H19: =IF(OR(C19="",D19=""),"",IF(OR(E19="",F19=""),"",IF(E19>F19,C19,IF(F19>E19,D19,IF(G19=1,C19,IF(G19=2,D19,"¿Penales?")))))) | I19: =IF(OR(C19="",D19=""),"",IF(OR(E19="",F19=""),"",IF(E19>F19,D19,IF(F19>E19,C19,IF(G19=1,D19,IF(G19=2,C19,"¿Penales?"))))))
A20: 89 | B20: Octavos | C20: =H5 | D20: =H8 | H20: =IF(OR(C20="",D20=""),"",IF(OR(E20="",F20=""),"",IF(E20>F20,C20,IF(F20>E20,D20,IF(G20=1,C20,IF(G20=2,D20,"¿Penales?")))))) | I20: =IF(OR(C20="",D20=""),"",IF(OR(E20="",F20=""),"",IF(E20>F20,D20,IF(F20>E20,C20,IF(G20=1,D20,IF(G20=2,C20,"¿Penales?"))))))
A21: 90 | B21: Octavos | C21: =H4 | D21: =H6 | H21: =IF(OR(C21="",D21=""),"",IF(OR(E21="",F21=""),"",IF(E21>F21,C21,IF(F21>E21,D21,IF(G21=1,C21,IF(G21=2,D21,"¿Penales?")))))) | I21: =IF(OR(C21="",D21=""),"",IF(OR(E21="",F21=""),"",IF(E21>F21,D21,IF(F21>E21,C21,IF(G21=1,D21,IF(G21=2,C21,"¿Penales?"))))))
A22: 91 | B22: Octavos | C22: =H7 | D22: =H9 | H22: =IF(OR(C22="",D22=""),"",IF(OR(E22="",F22=""),"",IF(E22>F22,C22,IF(F22>E22,D22,IF(G22=1,C22,IF(G22=2,D22,"¿Penales?")))))) | I22: =IF(OR(C22="",D22=""),"",IF(OR(E22="",F22=""),"",IF(E22>F22,D22,IF(F22>E22,C22,IF(G22=1,D22,IF(G22=2,C22,"¿Penales?"))))))
A23: 92 | B23: Octavos | C23: =H10 | D23: =H11 | H23: =IF(OR(C23="",D23=""),"",IF(OR(E23="",F23=""),"",IF(E23>F23,C23,IF(F23>E23,D23,IF(G23=1,C23,IF(G23=2,D23,"¿Penales?")))))) | I23: =IF(OR(C23="",D23=""),"",IF(OR(E23="",F23=""),"",IF(E23>F23,D23,IF(F23>E23,C23,IF(G23=1,D23,IF(G23=2,C23,"¿Penales?"))))))
A24: 93 | B24: Octavos | C24: =H14 | D24: =H15 | H24: =IF(OR(C24="",D24=""),"",IF(OR(E24="",F24=""),"",IF(E24>F24,C24,IF(F24>E24,D24,IF(G24=1,C24,IF(G24=2,D24,"¿Penales?")))))) | I24: =IF(OR(C24="",D24=""),"",IF(OR(E24="",F24=""),"",IF(E24>F24,D24,IF(F24>E24,C24,IF(G24=1,D24,IF(G24=2,C24,"¿Penales?"))))))
A25: 94 | B25: Octavos | C25: =H12 | D25: =H13 | H25: =IF(OR(C25="",D25=""),"",IF(OR(E25="",F25=""),"",IF(E25>F25,C25,IF(F25>E25,D25,IF(G25=1,C25,IF(G25=2,D25,"¿Penales?")))))) | I25: =IF(OR(C25="",D25=""),"",IF(OR(E25="",F25=""),"",IF(E25>F25,D25,IF(F25>E25,C25,IF(G25=1,D25,IF(G25=2,C25,"¿Penales?"))))))
A26: 95 | B26: Octavos | C26: =H17 | D26: =H19 | H26: =IF(OR(C26="",D26=""),"",IF(OR(E26="",F26=""),"",IF(E26>F26,C26,IF(F26>E26,D26,IF(G26=1,C26,IF(G26=2,D26,"¿Penales?")))))) | I26: =IF(OR(C26="",D26=""),"",IF(OR(E26="",F26=""),"",IF(E26>F26,D26,IF(F26>E26,C26,IF(G26=1,D26,IF(G26=2,C26,"¿Penales?"))))))
A27: 96 | B27: Octavos | C27: =H16 | D27: =H18 | H27: =IF(OR(C27="",D27=""),"",IF(OR(E27="",F27=""),"",IF(E27>F27,C27,IF(F27>E27,D27,IF(G27=1,C27,IF(G27=2,D27,"¿Penales?")))))) | I27: =IF(OR(C27="",D27=""),"",IF(OR(E27="",F27=""),"",IF(E27>F27,D27,IF(F27>E27,C27,IF(G27=1,D27,IF(G27=2,C27,"¿Penales?"))))))
A28: 97 | B28: Cuartos | C28: =H20 | D28: =H21 | H28: =IF(OR(C28="",D28=""),"",IF(OR(E28="",F28=""),"",IF(E28>F28,C28,IF(F28>E28,D28,IF(G28=1,C28,IF(G28=2,D28,"¿Penales?")))))) | I28: =IF(OR(C28="",D28=""),"",IF(OR(E28="",F28=""),"",IF(E28>F28,D28,IF(F28>E28,C28,IF(G28=1,D28,IF(G28=2,C28,"¿Penales?"))))))
A29: 98 | B29: Cuartos | C29: =H24 | D29: =H25 | H29: =IF(OR(C29="",D29=""),"",IF(OR(E29="",F29=""),"",IF(E29>F29,C29,IF(F29>E29,D29,IF(G29=1,C29,IF(G29=2,D29,"¿Penales?")))))) | I29: =IF(OR(C29="",D29=""),"",IF(OR(E29="",F29=""),"",IF(E29>F29,D29,IF(F29>E29,C29,IF(G29=1,D29,IF(G29=2,C29,"¿Penales?"))))))
A30: 99 | B30: Cuartos | C30: =H22 | D30: =H23 | H30: =IF(OR(C30="",D30=""),"",IF(OR(E30="",F30=""),"",IF(E30>F30,C30,IF(F30>E30,D30,IF(G30=1,C30,IF(G30=2,D30,"¿Penales?")))))) | I30: =IF(OR(C30="",D30=""),"",IF(OR(E30="",F30=""),"",IF(E30>F30,D30,IF(F30>E30,C30,IF(G30=1,D30,IF(G30=2,C30,"¿Penales?"))))))
A31: 100 | B31: Cuartos | C31: =H26 | D31: =H27 | H31: =IF(OR(C31="",D31=""),"",IF(OR(E31="",F31=""),"",IF(E31>F31,C31,IF(F31>E31,D31,IF(G31=1,C31,IF(G31=2,D31,"¿Penales?")))))) | I31: =IF(OR(C31="",D31=""),"",IF(OR(E31="",F31=""),"",IF(E31>F31,D31,IF(F31>E31,C31,IF(G31=1,D31,IF(G31=2,C31,"¿Penales?"))))))
A32: 101 | B32: Semifinal | C32: =H28 | D32: =H29 | H32: =IF(OR(C32="",D32=""),"",IF(OR(E32="",F32=""),"",IF(E32>F32,C32,IF(F32>E32,D32,IF(G32=1,C32,IF(G32=2,D32,"¿Penales?")))))) | I32: =IF(OR(C32="",D32=""),"",IF(OR(E32="",F32=""),"",IF(E32>F32,D32,IF(F32>E32,C32,IF(G32=1,D32,IF(G32=2,C32,"¿Penales?"))))))
A33: 102 | B33: Semifinal | C33: =H30 | D33: =H31 | H33: =IF(OR(C33="",D33=""),"",IF(OR(E33="",F33=""),"",IF(E33>F33,C33,IF(F33>E33,D33,IF(G33=1,C33,IF(G33=2,D33,"¿Penales?")))))) | I33: =IF(OR(C33="",D33=""),"",IF(OR(E33="",F33=""),"",IF(E33>F33,D33,IF(F33>E33,C33,IF(G33=1,D33,IF(G33=2,C33,"¿Penales?"))))))
A34: 103 | B34: Tercer puesto | C34: =I32 | D34: =I33 | H34: =IF(OR(C34="",D34=""),"",IF(OR(E34="",F34=""),"",IF(E34>F34,C34,IF(F34>E34,D34,IF(G34=1,C34,IF(G34=2,D34,"¿Penales?")))))) | I34: =IF(OR(C34="",D34=""),"",IF(OR(E34="",F34=""),"",IF(E34>F34,D34,IF(F34>E34,C34,IF(G34=1,D34,IF(G34=2,C34,"¿Penales?"))))))
A35: 104 | B35: Final | C35: =H32 | D35: =H33 | H35: =IF(OR(C35="",D35=""),"",IF(OR(E35="",F35=""),"",IF(E35>F35,C35,IF(F35>E35,D35,IF(G35=1,C35,IF(G35=2,D35,"¿Penales?")))))) | I35: =IF(OR(C35="",D35=""),"",IF(OR(E35="",F35=""),"",IF(E35>F35,D35,IF(F35>E35,C35,IF(G35=1,D35,IF(G35=2,C35,"¿Penales?"))))))

Sheet Podio
A1: 🏆 Podio Final (calculado a partir de Eliminatorias)
A3: 🥇 Campeón | B3: =IF(Eliminatorias!H35="","Pendiente",Eliminatorias!H35) -> Pendiente
A4: 🥈 Subcampeón | B4: =IF(Eliminatorias!I35="","Pendiente",Eliminatorias!I35) -> Pendiente
A5: 🥉 Tercer puesto | B5: =IF(Eliminatorias!H34="","Pendiente",Eliminatorias!H34) -> Pendiente
A7: Esta sección se llena sola cuando completes toda la pestaña "Eliminatorias". Si ves "Pendiente", significa que aún faltan marcadores por llenar en alguno de los partidos del camino hacia la final.

Sheet Grupos (referencia)
A1: 📋 Equipos por grupo (referencia)
A2: Grupo | B2: Equipo 1 | C2: Equipo 2 | D2: Equipo 3 | E2: Equipo 4
A3: Grupo A | B3: México | C3: Sudáfrica | D3: Corea del Sur | E3: Rep. Checa
A4: Grupo B | B4: Canadá | C4: Bosnia y Herzegovina | D4: Qatar | E4: Suiza
A5: Grupo C | B5: Brasil | C5: Marruecos | D5: Haití | E5: Escocia
A6: Grupo D | B6: Estados Unidos | C6: Paraguay | D6: Australia | E6: Turquía
A7: Grupo E | B7: Alemania | C7: Curazao | D7: Costa de Marfil | E7: Ecuador
A8: Grupo F | B8: Países Bajos | C8: Japón | D8: Suecia | E8: Túnez
A9: Grupo G | B9: Bélgica | C9: Egipto | D9: Irán | E9: Nueva Zelanda
A10: Grupo H | B10: España | C10: Cabo Verde | D10: Arabia Saudita | E10: Uruguay
A11: Grupo I | B11: Francia | C11: Senegal | D11: Irak | E11: Noruega
A12: Grupo J | B12: Argentina | C12: Argelia | D12: Austria | E12: Jordania
A13: Grupo K | B13: Portugal | C13: Rep. Dem. del Congo | D13: Uzbekistán | E13: Colombia
A14: Grupo L | B14: Inglaterra | C14: Croacia | D14: Ghana | E14: Panamá
